2024-03-13 06:24:44 | ERROR    | __main__:run:158 | An error has been caught in function 'run', process 'MainProcess' (4156), thread 'MainThread' (139713908079488): - {}
Traceback (most recent call last):
  File "/opt/hostedtoolcache/Python/3.10.13/x64/lib/python3.10/site-packages/httpx/_transports/default.py", line 69, in map_httpcore_exceptions
    yield
  File "/opt/hostedtoolcache/Python/3.10.13/x64/lib/python3.10/site-packages/httpx/_transports/default.py", line 233, in handle_request
    resp = self._pool.handle_request(req)
  File "/opt/hostedtoolcache/Python/3.10.13/x64/lib/python3.10/site-packages/httpcore/_sync/connection_pool.py", line 216, in handle_request
    raise exc from None
  File "/opt/hostedtoolcache/Python/3.10.13/x64/lib/python3.10/site-packages/httpcore/_sync/connection_pool.py", line 196, in handle_request
    response = connection.handle_request(
  File "/opt/hostedtoolcache/Python/3.10.13/x64/lib/python3.10/site-packages/httpcore/_sync/connection.py", line 101, in handle_request
    return self._connection.handle_request(request)
  File "/opt/hostedtoolcache/Python/3.10.13/x64/lib/python3.10/site-packages/httpcore/_sync/http11.py", line 143, in handle_request
    raise exc
  File "/opt/hostedtoolcache/Python/3.10.13/x64/lib/python3.10/site-packages/httpcore/_sync/http11.py", line 113, in handle_request
    ) = self._receive_response_headers(**kwargs)
  File "/opt/hostedtoolcache/Python/3.10.13/x64/lib/python3.10/site-packages/httpcore/_sync/http11.py", line 186, in _receive_response_headers
    event = self._receive_event(timeout=timeout)
  File "/opt/hostedtoolcache/Python/3.10.13/x64/lib/python3.10/site-packages/httpcore/_sync/http11.py", line 224, in _receive_event
    data = self._network_stream.read(
  File "/opt/hostedtoolcache/Python/3.10.13/x64/lib/python3.10/site-packages/httpcore/_backends/sync.py", line 124, in read
    with map_exceptions(exc_map):
  File "/opt/hostedtoolcache/Python/3.10.13/x64/lib/python3.10/contextlib.py", line 153, in __exit__
    self.gen.throw(typ, value, traceback)
  File "/opt/hostedtoolcache/Python/3.10.13/x64/lib/python3.10/site-packages/httpcore/_exceptions.py", line 14, in map_exceptions
    raise to_exc(exc) from exc
httpcore.ReadTimeout: The read operation timed out

The above exception was the direct cause of the following exception:

Traceback (most recent call last):
  File "/home/runner/work/epic-free/epic-free/epic/src/claim.py", line 162, in <module>
    asyncio.run(run())
  File "/opt/hostedtoolcache/Python/3.10.13/x64/lib/python3.10/asyncio/runners.py", line 44, in run
    return loop.run_until_complete(main)
  File "/opt/hostedtoolcache/Python/3.10.13/x64/lib/python3.10/asyncio/base_events.py", line 636, in run_until_complete
    self.run_forever()
  File "/opt/hostedtoolcache/Python/3.10.13/x64/lib/python3.10/asyncio/base_events.py", line 603, in run_forever
    self._run_once()
  File "/opt/hostedtoolcache/Python/3.10.13/x64/lib/python3.10/asyncio/base_events.py", line 1909, in _run_once
    handle._run()
  File "/opt/hostedtoolcache/Python/3.10.13/x64/lib/python3.10/asyncio/events.py", line 80, in _run
    self._context.run(self._callback, *self._args)
> File "/home/runner/work/epic-free/epic-free/epic/src/claim.py", line 158, in run
    await agent.stash()
  File "/home/runner/work/epic-free/epic-free/epic/src/claim.py", line 151, in stash
    await self.claim_epic_games(context)
  File "/home/runner/work/epic-free/epic-free/epic/src/claim.py", line 106, in claim_epic_games
    self.create_tasks()
  File "/home/runner/work/epic-free/epic-free/epic/src/claim.py", line 64, in create_tasks
    self._pros = get_promotions()
  File "/home/runner/work/epic-free/epic-free/epic/src/epic_games/agent.py", line 411, in get_promotions
    resp = httpx.get(URL_PROMOTIONS, params=params)
  File "/opt/hostedtoolcache/Python/3.10.13/x64/lib/python3.10/site-packages/httpx/_api.py", line 198, in get
    return request(
  File "/opt/hostedtoolcache/Python/3.10.13/x64/lib/python3.10/site-packages/httpx/_api.py", line 106, in request
    return client.request(
  File "/opt/hostedtoolcache/Python/3.10.13/x64/lib/python3.10/site-packages/httpx/_client.py", line 827, in request
    return self.send(request, auth=auth, follow_redirects=follow_redirects)
  File "/opt/hostedtoolcache/Python/3.10.13/x64/lib/python3.10/site-packages/httpx/_client.py", line 914, in send
    response = self._send_handling_auth(
  File "/opt/hostedtoolcache/Python/3.10.13/x64/lib/python3.10/site-packages/httpx/_client.py", line 942, in _send_handling_auth
    response = self._send_handling_redirects(
  File "/opt/hostedtoolcache/Python/3.10.13/x64/lib/python3.10/site-packages/httpx/_client.py", line 979, in _send_handling_redirects
    response = self._send_single_request(request)
  File "/opt/hostedtoolcache/Python/3.10.13/x64/lib/python3.10/site-packages/httpx/_client.py", line 1015, in _send_single_request
    response = transport.handle_request(request)
  File "/opt/hostedtoolcache/Python/3.10.13/x64/lib/python3.10/site-packages/httpx/_transports/default.py", line 232, in handle_request
    with map_httpcore_exceptions():
  File "/opt/hostedtoolcache/Python/3.10.13/x64/lib/python3.10/contextlib.py", line 153, in __exit__
    self.gen.throw(typ, value, traceback)
  File "/opt/hostedtoolcache/Python/3.10.13/x64/lib/python3.10/site-packages/httpx/_transports/default.py", line 86, in map_httpcore_exceptions
    raise mapped_exc(message) from exc
httpx.ReadTimeout: The read operation timed out
